<?xml version="1.0" ?>
<!-- =================================================================================== -->
<!-- |    This document was autogenerated by xacro from /home/Shared/delicious/ada/workspace/install/ada_description/share/ada_description/urdf/ada.xacro | -->
<!-- |    EDITING THIS FILE BY HAND IS NOT RECOMMENDED                                 | -->
<!-- =================================================================================== -->
<robot name="ada" xmlns:body="http://playerstage.sourceforge.net/gazebo/xmlschema/#body" xmlns:controller="http://playerstage.sourceforge.net/gazebo/xmlschema/#controller" xmlns:gazebo="http://playerstage.sourceforge.net/gazebo/xmlschema/#gz" xmlns:geom="http://playerstage.sourceforge.net/gazebo/xmlschema/#geom" xmlns:interface="http://playerstage.sourceforge.net/gazebo/xmlschema/#interface" xmlns:joint="http://playerstage.sourceforge.net/gazebo/xmlschema/#joint" xmlns:model="http://playerstage.sourceforge.net/gazebo/xmlschema/#model" xmlns:physics="http://playerstage.sourceforge.net/gazebo/xmlschema/#physics" xmlns:renderable="http://playerstage.sourceforge.net/gazebo/xmlschema/#renderable" xmlns:rendering="http://playerstage.sourceforge.net/gazebo/xmlschema/#rendering" xmlns:sensor="http://playerstage.sourceforge.net/gazebo/xmlschema/#sensor" xmlns:xi="http://www.w3.org/2001/XInclude">
  <material name="aluminum">
    <color rgba="0.4 0.4 0.4 1"/>
  </material>
  <material name="plastic">
    <color rgba="0.1 0.1 0.1 1"/>
  </material>
  <link name="root"/>
  <link name="root_tilt"/>
  <joint name="robot_tilt" type="revolute">
    <origin rpy="0 0 0" xyz="0 0 0"/>
    <child link="root_tilt"/>
    <parent link="root"/>
    <axis xyz="-1 0 0"/>
    <!-- effort copied from j2n6s200 joint 2, velocity is max velocity the wheelchair can tilt,
    lower and upper limits generously encompass the range of the wheelchair's tilt-->
    <limit effort="80" lower="-3.141592653589793" upper="3.141592653589793" velocity="0.15"/>
    <dynamics damping="0.0" friction="0.0"/>
  </joint>
  <!--xacro:j2n6s200 base_parent="${robot_root}"/-->
  <joint name="ada_base_joint" type="fixed">
    <origin rpy="0 0 0" xyz="0 0 0"/>
    <parent link="root_tilt"/>
    <child link="ada_base_link"/>
  </joint>
  <link name="ada_base_link">
    <inertial>
      <origin rpy="0 0 0" xyz="-0.000648 -0.000166 0.084487"/>
      <mass value="1.697"/>
      <inertia ixx="0.004622" ixy="9E-06" ixz="6E-05" iyy="0.004495" iyz="9E-06" izz="0.002079"/>
    </inertial>
    <visual>
      <origin rpy="0 0 0" xyz="0 0 0"/>
      <geometry>
        <mesh filename="package://kortex_description/arms/gen3/7dof/meshes/base_link.dae"/>
      </geometry>
      <material name="">
        <color rgba="0.75294 0.75294 0.75294 1"/>
      </material>
    </visual>
    <collision>
      <origin rpy="0 0 0" xyz="0 0 0"/>
      <geometry>
        <mesh filename="package://kortex_description/arms/gen3/7dof/meshes/base_link.dae"/>
      </geometry>
    </collision>
  </link>
  <link name="ada_shoulder_link">
    <inertial>
      <origin rpy="0 0 0" xyz="-2.3E-05 -0.010364 -0.07336"/>
      <mass value="1.3773"/>
      <inertia ixx="0.00457" ixy="1E-06" ixz="2E-06" iyy="0.004831" iyz="0.000448" izz="0.001409"/>
    </inertial>
    <visual>
      <origin rpy="0 0 0" xyz="0 0 0"/>
      <geometry>
        <mesh filename="package://kortex_description/arms/gen3/7dof/meshes/shoulder_link.dae"/>
      </geometry>
      <material name="">
        <color rgba="0.75294 0.75294 0.75294 1"/>
      </material>
    </visual>
    <collision>
      <origin rpy="0 0 0" xyz="0 0 0"/>
      <geometry>
        <mesh filename="package://kortex_description/arms/gen3/7dof/meshes/shoulder_link.dae"/>
      </geometry>
    </collision>
  </link>
  <joint name="ada_joint_1" type="continuous">
    <origin rpy="3.1416 2.7629E-18 -4.9305E-36" xyz="0 0 0.15643"/>
    <parent link="ada_base_link"/>
    <child link="ada_shoulder_link"/>
    <axis xyz="0 0 1"/>
    <limit effort="39" velocity="1.3963"/>
  </joint>
  <link name="ada_half_arm_1_link">
    <inertial>
      <origin rpy="0 0 0" xyz="-4.4E-05 -0.09958 -0.013278"/>
      <mass value="1.1636"/>
      <inertia ixx="0.011088" ixy="5E-06" ixz="0" iyy="0.001072" iyz="-0.000691" izz="0.011255"/>
    </inertial>
    <visual>
      <origin rpy="0 0 0" xyz="0 0 0"/>
      <geometry>
        <mesh filename="package://kortex_description/arms/gen3/7dof/meshes/half_arm_1_link.dae"/>
      </geometry>
      <material name="">
        <color rgba="0.75294 0.75294 0.75294 1"/>
      </material>
    </visual>
    <collision>
      <origin rpy="0 0 0" xyz="0 0 0"/>
      <geometry>
        <mesh filename="package://kortex_description/arms/gen3/7dof/meshes/half_arm_1_link.dae"/>
      </geometry>
    </collision>
  </link>
  <joint name="ada_joint_2" type="revolute">
    <origin rpy="1.5708 2.1343E-17 -1.1102E-16" xyz="0 0.005375 -0.12838"/>
    <parent link="ada_shoulder_link"/>
    <child link="ada_half_arm_1_link"/>
    <axis xyz="0 0 1"/>
    <limit effort="39" lower="-2.24" upper="2.24" velocity="1.3963"/>
  </joint>
  <link name="ada_half_arm_2_link">
    <inertial>
      <origin rpy="0 0 0" xyz="-4.4E-05 -0.006641 -0.117892"/>
      <mass value="1.1636"/>
      <inertia ixx="0.010932" ixy="0" ixz="-7E-06" iyy="0.011127" iyz="0.000606" izz="0.001043"/>
    </inertial>
    <visual>
      <origin rpy="0 0 0" xyz="0 0 0"/>
      <geometry>
        <mesh filename="package://kortex_description/arms/gen3/7dof/meshes/half_arm_2_link.dae"/>
      </geometry>
      <material name="">
        <color rgba="0.75294 0.75294 0.75294 1"/>
      </material>
    </visual>
    <collision>
      <origin rpy="0 0 0" xyz="0 0 0"/>
      <geometry>
        <mesh filename="package://kortex_description/arms/gen3/7dof/meshes/half_arm_2_link.dae"/>
      </geometry>
    </collision>
  </link>
  <joint name="ada_joint_3" type="continuous">
    <origin rpy="-1.5708 1.2326E-32 -2.9122E-16" xyz="0 -0.21038 -0.006375"/>
    <parent link="ada_half_arm_1_link"/>
    <child link="ada_half_arm_2_link"/>
    <axis xyz="0 0 1"/>
    <limit effort="39" velocity="1.3963"/>
  </joint>
  <link name="ada_forearm_link">
    <inertial>
      <origin rpy="0 0 0" xyz="-1.8E-05 -0.075478 -0.015006"/>
      <mass value="0.9302"/>
      <inertia ixx="0.008147" ixy="-1E-06" ixz="0" iyy="0.000631" iyz="-0.0005" izz="0.008316"/>
    </inertial>
    <visual>
      <origin rpy="0 0 0" xyz="0 0 0"/>
      <geometry>
        <mesh filename="package://kortex_description/arms/gen3/7dof/meshes/forearm_link.dae"/>
      </geometry>
      <material name="">
        <color rgba="0.75294 0.75294 0.75294 1"/>
      </material>
    </visual>
    <collision>
      <origin rpy="0 0 0" xyz="0 0 0"/>
      <geometry>
        <mesh filename="package://kortex_description/arms/gen3/7dof/meshes/forearm_link.dae"/>
      </geometry>
    </collision>
  </link>
  <joint name="ada_joint_4" type="revolute">
    <origin rpy="1.5708 -6.6954E-17 -1.6653E-16" xyz="0 0.006375 -0.21038"/>
    <parent link="ada_half_arm_2_link"/>
    <child link="ada_forearm_link"/>
    <axis xyz="0 0 1"/>
    <limit effort="39" lower="-2.57" upper="2.57" velocity="1.3963"/>
  </joint>
  <link name="ada_spherical_wrist_1_link">
    <inertial>
      <origin rpy="0 0 0" xyz="1E-06 -0.009432 -0.063883"/>
      <mass value="0.6781"/>
      <inertia ixx="0.001596" ixy="0" ixz="0" iyy="0.001607" iyz="0.000256" izz="0.000399"/>
    </inertial>
    <visual>
      <origin rpy="0 0 0" xyz="0 0 0"/>
      <geometry>
        <mesh filename="package://kortex_description/arms/gen3/7dof/meshes/spherical_wrist_1_link.dae"/>
      </geometry>
      <material name="">
        <color rgba="0.75294 0.75294 0.75294 1"/>
      </material>
    </visual>
    <collision>
      <origin rpy="0 0 0" xyz="0 0 0"/>
      <geometry>
        <mesh filename="package://kortex_description/arms/gen3/7dof/meshes/spherical_wrist_1_link.dae"/>
      </geometry>
    </collision>
  </link>
  <joint name="ada_joint_5" type="continuous">
    <origin rpy="-1.5708 2.2204E-16 -6.373E-17" xyz="0 -0.20843 -0.006375"/>
    <parent link="ada_forearm_link"/>
    <child link="ada_spherical_wrist_1_link"/>
    <axis xyz="0 0 1"/>
    <limit effort="9" velocity="1.2218"/>
  </joint>
  <link name="ada_spherical_wrist_2_link">
    <inertial>
      <origin rpy="0 0 0" xyz="1E-06 -0.045483 -0.00965"/>
      <mass value="0.6781"/>
      <inertia ixx="0.001641" ixy="0" ixz="0" iyy="0.00041" iyz="-0.000278" izz="0.001641"/>
    </inertial>
    <visual>
      <origin rpy="0 0 0" xyz="0 0 0"/>
      <geometry>
        <mesh filename="package://kortex_description/arms/gen3/7dof/meshes/spherical_wrist_2_link.dae"/>
      </geometry>
      <material name="">
        <color rgba="0.75294 0.75294 0.75294 1"/>
      </material>
    </visual>
    <collision>
      <origin rpy="0 0 0" xyz="0 0 0"/>
      <geometry>
        <mesh filename="package://kortex_description/arms/gen3/7dof/meshes/spherical_wrist_2_link.dae"/>
      </geometry>
    </collision>
  </link>
  <joint name="ada_joint_6" type="revolute">
    <origin rpy="1.5708 9.2076E-28 -8.2157E-15" xyz="0 0.00017505 -0.10593"/>
    <parent link="ada_spherical_wrist_1_link"/>
    <child link="ada_spherical_wrist_2_link"/>
    <axis xyz="0 0 1"/>
    <limit effort="9" lower="-2.09" upper="2.09" velocity="1.2218"/>
  </joint>
  <link name="ada_bracelet_link">
    <inertial>
      <origin rpy="0 0 0" xyz="0.000281 0.011402 -0.029798"/>
      <mass value="0.5"/>
      <inertia ixx="0.000587" ixy="3E-06" ixz="3E-06" iyy="0.000369" iyz="-0.000118" izz="0.000609"/>
    </inertial>
    <visual>
      <origin rpy="0 0 0" xyz="0 0 0"/>
      <geometry>
        <mesh filename="package://kortex_description/arms/gen3/7dof/meshes/bracelet_with_vision_link.dae"/>
      </geometry>
      <material name="">
        <color rgba="0.75294 0.75294 0.75294 1"/>
      </material>
    </visual>
    <collision>
      <origin rpy="0 0 0" xyz="0 0 0"/>
      <geometry>
        <mesh filename="package://kortex_description/arms/gen3/7dof/meshes/bracelet_with_vision_link.dae"/>
      </geometry>
    </collision>
  </link>
  <joint name="ada_joint_7" type="continuous">
    <origin rpy="-1.5708 -5.5511E-17 9.6396E-17" xyz="0 -0.10593 -0.00017505"/>
    <parent link="ada_spherical_wrist_2_link"/>
    <child link="ada_bracelet_link"/>
    <axis xyz="0 0 1"/>
    <limit effort="9" velocity="1.2218"/>
  </joint>
  <link name="ada_end_effector_link"/>
  <joint name="ada_end_effector" type="fixed">
    <origin rpy="3.14159265358979 1.09937075168372E-32 0" xyz="0 0 -0.0615250000000001"/>
    <parent link="ada_bracelet_link"/>
    <child link="ada_end_effector_link"/>
    <axis xyz="0 0 0"/>
  </joint>
  <link name="ada_camera_link"/>
  <joint name="ada_camera_module" type="fixed">
    <origin rpy="3.141592653589793 3.141592653589793 0" xyz="0 0.05639 -0.00305"/>
    <parent link="ada_end_effector_link"/>
    <child link="ada_camera_link"/>
  </joint>
  <link name="ada_camera_depth_frame"/>
  <joint name="ada_depth_module" type="fixed">
    <origin rpy="3.141592653589793 3.141592653589793 0" xyz="0.0275 0.066 -0.00305"/>
    <parent link="ada_end_effector_link"/>
    <child link="ada_camera_depth_frame"/>
  </joint>
  <link name="ada_camera_color_frame"/>
  <joint name="ada_color_module" type="fixed">
    <origin rpy="3.141592653589793 3.141592653589793 0" xyz="0 0.05639 -0.00305"/>
    <parent link="ada_end_effector_link"/>
    <child link="ada_camera_color_frame"/>
  </joint>
  <link name="ada_tool_frame"/>
  <joint name="ada_tool_frame_joint" type="fixed">
    <origin rpy="0 0 0" xyz="0 0 0"/>
    <parent link="ada_end_effector_link"/>
    <child link="ada_tool_frame"/>
    <axis xyz="0 0 0"/>
  </joint>
  <!--xacro:camera_assembly
    base_parent="j2n6s200_link_6"
    base_xyz="0.0165 0 0.0011"
    base_rpy="${3*J_PI/2} 0 ${3*J_PI/2}"
  / gurnoork comment -->
  <link name="nanoMount">
    <visual>
      <geometry>
        <mesh filename="package://ada_description/meshes/camera/2023_03_09_nanoArmMount.stl" scale="0.001 0.001 0.001"/>
      </geometry>
      <material name="abs">
        <color rgba="0.4 0.4 0.4 1"/>
      </material>
    </visual>
    <collision>
      <geometry>
        <mesh filename="package://ada_description/meshes/camera/2023_03_09_nanoArmMount.stl" scale="0.001 0.001 0.001"/>
      </geometry>
    </collision>
    <inertial>
      <origin rpy="0 0 0" xyz="-0.002400 0.0046958 0.0115245"/>
      <mass value="0.008"/>
      <inertia ixx="0.00000095025" ixy="-0.000000297842" ixz="-0.00000000010444" iyy="0.0000067325" iyz="0.000000000470196" izz="0.0000069433"/>
    </inertial>
  </link>
  <joint name="nanoMount_to_world" type="fixed">
    <parent link="ada_end_effector_link"/>
    <child link="nanoMount"/>
    <axis xyz="0 0 1"/>
    <origin rpy="4.71238898038469 0 4.71238898038469" xyz="0.0165 0 0.0011"/>
  </joint>
  <link name="enclosureBottom">
    <visual>
      <geometry>
        <mesh filename="package://ada_description/meshes/camera/2023_09_28_nanoEnclosureBottom.stl" scale="0.001 0.001 0.001"/>
      </geometry>
      <material name="abs">
        <color rgba="0.4 0.4 0.4 1"/>
      </material>
    </visual>
    <collision>
      <geometry>
        <mesh filename="package://ada_description/meshes/camera/2023_09_28_nanoEnclosureBottom.stl" scale="0.001 0.001 0.001"/>
      </geometry>
    </collision>
    <inertial>
      <origin rpy="0 0 0" xyz="0.0546451 0.0472161 0.00043655"/>
      <mass value="0.04"/>
      <inertia ixx="0.000041028" ixy="-0.000000324" ixz="-0.00000045367" iyy="0.000083168" iyz="0.0000026243" izz="0.000116424"/>
    </inertial>
  </link>
  <joint name="enclosureBottom_to_nanoMount" type="fixed">
    <parent link="nanoMount"/>
    <child link="enclosureBottom"/>
    <axis xyz="0 0 1"/>
    <origin rpy="0 0 1.5707963267948966" xyz="0.0412 -0.0218 0.026"/>
  </joint>
  <link name="nano">
    <visual>
      <geometry>
        <mesh filename="package://ada_description/meshes/camera/2023_03_21_jetsonNano.stl" scale="0.001 0.001 0.001"/>
      </geometry>
      <material name="abs">
        <color rgba="0.4 0.4 0.4 1"/>
      </material>
    </visual>
    <collision>
      <geometry>
        <mesh filename="package://ada_description/meshes/camera/2023_03_21_jetsonNano.stl" scale="0.001 0.001 0.001"/>
      </geometry>
    </collision>
    <inertial>
      <origin rpy="0 0 0" xyz="0.0435615 0.02502709 0.0091247"/>
      <mass value="0.142"/>
      <inertia ixx="0.000077456" ixy="-0.000004935" ixz="0.0000015461" iyy="0.0001013" iyz="0.0000036951" izz="0.0001727"/>
    </inertial>
  </link>
  <joint name="nano_to_enclosureBottom" type="fixed">
    <parent link="enclosureBottom"/>
    <child link="nano"/>
    <axis xyz="0 0 1"/>
    <origin rpy="0 0 0" xyz="0.0105 0.014 -0.0015"/>
  </joint>
  <link name="frontStabilizer">
    <visual>
      <geometry>
        <mesh filename="package://ada_description/meshes/camera/2023_09_21_nanoEnclosureFrontStabilizer.stl" scale="0.001 0.001 0.001"/>
      </geometry>
      <material name="abs">
        <color rgba="0.4 0.4 0.4 1"/>
      </material>
    </visual>
    <collision>
      <geometry>
        <mesh filename="package://ada_description/meshes/camera/2023_09_21_nanoEnclosureFrontStabilizer.stl" scale="0.001 0.001 0.001"/>
      </geometry>
    </collision>
    <inertial>
      <origin rpy="0 0 0" xyz="-0.008107 -0.000955 0.02045"/>
      <mass value="0.0198"/>
      <inertia ixx="0.00000074776" ixy="0.000000000071856" ixz="0.0000000002764" iyy="0.0000118843" iyz="0.00000001021778" izz="0.0000119096"/>
    </inertial>
  </link>
  <joint name="frontStabilizer_to_enclosureBottom" type="fixed">
    <parent link="enclosureBottom"/>
    <child link="frontStabilizer"/>
    <axis xyz="0 0 1"/>
    <origin rpy="0 0 1.5707963267948966" xyz="0.1063 0.0493 -0.0363"/>
  </joint>
  <link name="enclosureTop">
    <visual>
      <geometry>
        <mesh filename="package://ada_description/meshes/camera/2023_06_06_nanoEnclosureTopCameraBack.stl" scale="0.001 0.001 0.001"/>
      </geometry>
      <material name="abs">
        <color rgba="0.4 0.4 0.4 1"/>
      </material>
    </visual>
    <collision>
      <geometry>
        <mesh filename="package://ada_description/meshes/camera/2023_06_06_nanoEnclosureTopCameraBack.stl" scale="0.001 0.001 0.001"/>
      </geometry>
    </collision>
    <inertial>
      <origin rpy="0 0 0" xyz="0.041228 0.006275 0.016379"/>
      <mass value="0.046"/>
      <inertia ixx="0.00005942" ixy="-0.000000046193" ixz="0.0000091699" iyy="0.000085611" iyz="0.0000012783" izz="0.000126390"/>
    </inertial>
  </link>
  <joint name="enclosureTop_to_enclosureBottom" type="fixed">
    <parent link="enclosureBottom"/>
    <child link="enclosureTop"/>
    <axis xyz="0 0 1"/>
    <origin rpy="0 2.886774582798621 3.141592653589793" xyz="0.009925 0.04099 0.05442"/>
  </joint>
  <link name="cameraMount">
    <visual>
      <geometry>
        <mesh filename="package://ada_description/meshes/camera/2023_06_06_cameraBackMount.stl" scale="0.001 0.001 0.001"/>
      </geometry>
      <material name="abs">
        <color rgba="0.4 0.4 0.4 1"/>
      </material>
    </visual>
    <collision>
      <geometry>
        <mesh filename="package://ada_description/meshes/camera/2023_06_06_cameraBackMount.stl" scale="0.001 0.001 0.001"/>
      </geometry>
    </collision>
    <inertial>
      <origin rpy="0 0 0" xyz="-0.007986 0 0.010064"/>
      <mass value="0.004"/>
      <inertia ixx="0.000002782" ixy="-0.00000000002321" ixz="0.000000074385" iyy="00.0000005528" iyz="-0.00000000000178" izz="0.000002964"/>
    </inertial>
  </link>
  <joint name="cameraMount_to_enclosureTop" type="fixed">
    <parent link="enclosureTop"/>
    <child link="cameraMount"/>
    <axis xyz="0 0 1"/>
    <origin rpy="0 1.5707963267948966 0" xyz="-0.0132 0 -0.022"/>
  </joint>
  <link name="screwHeadLeft">
    <visual>
      <geometry>
        <mesh filename="package://ada_description/meshes/camera/2023_11_07_screwHead.stl" scale="0.001 0.001 0.001"/>
      </geometry>
      <material name="abs">
        <color rgba="0.4 0.4 0.4 1"/>
      </material>
    </visual>
    <collision>
      <geometry>
        <mesh filename="package://ada_description/meshes/camera/2023_11_07_screwHead.stl" scale="0.001 0.001 0.001"/>
      </geometry>
    </collision>
    <inertial>
      <origin rpy="0 0 0" xyz="0 0 0.0015"/>
      <mass value="0.0001"/>
      <inertia ixx="0.000000000342785" ixy="0" ixz="0" iyy="0.000000000342785" iyz="0" izz="0.000000000543538"/>
    </inertial>
  </link>
  <joint name="screwHeadLeft_to_cameraMount" type="fixed">
    <parent link="cameraMount"/>
    <child link="screwHeadLeft"/>
    <axis xyz="0 0 1"/>
    <origin rpy="3.141592653589793 0 0" xyz="0.0165 -0.0225 0"/>
  </joint>
  <link name="screwHeadRight">
    <visual>
      <geometry>
        <mesh filename="package://ada_description/meshes/camera/2023_11_07_screwHead.stl" scale="0.001 0.001 0.001"/>
      </geometry>
      <material name="abs">
        <color rgba="0.4 0.4 0.4 1"/>
      </material>
    </visual>
    <collision>
      <geometry>
        <mesh filename="package://ada_description/meshes/camera/2023_11_07_screwHead.stl" scale="0.001 0.001 0.001"/>
      </geometry>
    </collision>
    <inertial>
      <origin rpy="0 0 0" xyz="0 0 0.0015"/>
      <mass value="0.0001"/>
      <inertia ixx="0.000000000342785" ixy="0" ixz="0" iyy="0.000000000342785" iyz="0" izz="0.000000000543538"/>
    </inertial>
  </link>
  <joint name="screwHeadRight_to_cameraMount" type="fixed">
    <parent link="cameraMount"/>
    <child link="screwHeadRight"/>
    <axis xyz="0 0 1"/>
    <origin rpy="3.141592653589793 0 0" xyz="0.0165 0.0225 0"/>
  </joint>
  <!-- camera body, with origin at bottom screw mount -->
  <joint name="uncalibrated_camera_joint" type="fixed">
    <origin rpy="0 -1.5707963267948966 3.141592653589793" xyz="0.006 0 0.013"/>
    <parent link="cameraMount"/>
    <child link="uncalibrated_camera_bottom_screw_frame"/>
  </joint>
  <link name="uncalibrated_camera_bottom_screw_frame"/>
  <joint name="uncalibrated_camera_link_joint" type="fixed">
    <origin rpy="0 0 0" xyz="0 0.02 0.0115"/>
    <parent link="uncalibrated_camera_bottom_screw_frame"/>
    <child link="uncalibrated_camera_link"/>
  </joint>
  <link name="uncalibrated_camera_link">
    <visual>
      <origin rpy="1.5707963267948966 0 1.5707963267948966" xyz="0.00987 -0.02 0"/>
      <geometry>
        <mesh filename="package://ada_description/meshes/camera/d415.stl"/>
      </geometry>
      <material name="aluminum"/>
    </visual>
    <collision>
      <origin rpy="0 0 0" xyz="0 -0.02 0"/>
      <geometry>
        <box size="0.02005 0.099 0.023"/>
      </geometry>
    </collision>
    <inertial>
      <mass value="0.0589"/>
      <!-- manufacturer's value: 0.072 -->
      <origin xyz="0 -0.02 0"/>
      <inertia ixx="0.00005491" ixy="-0.0000000249492" ixz="0.00000004862028" iyy="0.00000521068" iyz="0.00000000857625" izz="0.0000554597"/>
    </inertial>
  </link>
  <!-- Hard-coded Extrinsics -->
  <link name="camera_link"/>
  <joint name="extrinsics" type="fixed">
    <origin rpy="0.17234 -1.56127 2.96967" xyz="0.0194 -0.01606 0.029014"/>
    <parent link="cameraMount"/>
    <child link="camera_link"/>
  </joint>
  <!-- Copy Realsense in case of simulation -->
  <!--
  <link name="camera_color_optical_frame" />
  <joint name="optical_republish" type="fixed">
    <origin xyz="0.000 -0.015 0.000" rpy="-1.564 0.000 -1.573" />
    <parent link="camera_link" />
    <child link="camera_color_optical_frame" />
  </joint>
  -->
  <link name="FTArmMount">
    <visual>
      <geometry>
        <mesh filename="package://ada_description/meshes/forque/2024_01_18_FTArmMount.stl" scale="0.001 0.001 0.001"/>
      </geometry>
      <material name="abs">
        <color rgba="0.4 0.4 0.4 1"/>
      </material>
    </visual>
    <collision>
      <geometry>
        <mesh filename="package://ada_description/meshes/forque/2024_01_18_FTArmMount.stl" scale="0.001 0.001 0.001"/>
      </geometry>
    </collision>
    <inertial>
      <origin rpy="0 0 0" xyz="0.010957 -0.019223 -0.03777"/>
      <mass value="0.03783"/>
      <inertia ixx="0.000018817" ixy="-0.0000003327" ixz="-0.000000092476" iyy="0.00001119989" iyz="-0.00000120296" izz="0.000026883"/>
    </inertial>
  </link>
  <joint name="FTArmMount_to_arm" type="fixed">
    <parent link="ada_end_effector_link"/>
    <child link="FTArmMount"/>
    <axis xyz="0 0 1"/>
    <origin rpy="1.5707963267948966 0 1.5707963267948966" xyz="0.0065 -0.011 -0.0075"/>
  </joint>
  <link name="FTMount">
    <visual>
      <geometry>
        <mesh filename="package://ada_description/meshes/forque/2024_01_18_FTMount.stl" scale="0.001 0.001 0.001"/>
      </geometry>
      <material name="abs">
        <color rgba="0.4 0.4 0.4 1"/>
      </material>
    </visual>
    <collision>
      <geometry>
        <mesh filename="package://ada_description/meshes/forque/2024_01_18_FTMount.stl" scale="0.001 0.001 0.001"/>
      </geometry>
    </collision>
    <inertial>
      <origin rpy="0 0 0" xyz="0.010934 -0.138522 -0.05066"/>
      <mass value="0.103"/>
      <inertia ixx="0.00017623" ixy="0.00000095729" ixz="-0.0000000562908" iyy="0.000068428" iyz="-0.00001757133" izz="0.00021455"/>
    </inertial>
  </link>
  <joint name="FTMount_to_world" type="fixed">
    <parent link="FTArmMount"/>
    <child link="FTMount"/>
    <axis xyz="0 0 1"/>
    <origin rpy="0 0 0" xyz="0 0 -0.005"/>
  </joint>
  <link name="FT">
    <visual>
      <geometry>
        <mesh filename="package://ada_description/meshes/forque/2023_03_09_wirelessFT.stl" scale="0.001 0.001 0.001"/>
      </geometry>
      <material name="abs">
        <color rgba="0.4 0.4 0.4 1"/>
      </material>
    </visual>
    <collision>
      <geometry>
        <mesh filename="package://ada_description/meshes/forque/2023_03_09_wirelessFT.stl" scale="0.001 0.001 0.001"/>
      </geometry>
    </collision>
    <inertial>
      <origin rpy="0 0 0" xyz="0.0111446 -0.0882070 -0.0544936"/>
      <mass value="0.28"/>
      <inertia ixx="0.000543925" ixy="-0.00000128367" ixz="0" iyy="0.000165428" iyz="-0.00000001487288" izz="0.000691232"/>
    </inertial>
  </link>
  <joint name="FT_to_FTMount" type="fixed">
    <parent link="FTMount"/>
    <child link="FT"/>
    <axis xyz="0 0 1"/>
    <origin rpy="0 0 0" xyz="0 0 0"/>
  </joint>
  <link name="forkHandle">
    <visual>
      <geometry>
        <mesh filename="package://ada_description/meshes/forque/2024_06_24_forkHandleHollow.stl" scale="0.001 0.001 0.001"/>
      </geometry>
      <material name="abs">
        <color rgba="0.4 0.4 0.4 1"/>
      </material>
    </visual>
    <collision>
      <geometry>
        <mesh filename="package://ada_description/meshes/forque/2024_06_24_forkHandleHollow.stl" scale="0.001 0.001 0.001"/>
      </geometry>
    </collision>
    <inertial>
      <origin rpy="0 0 0" xyz="0.011097 -0.162629 -0.011948"/>
      <mass value="0.028"/>
      <inertia ixx="0.00003114" ixy="-0.00000050626" ixz="0.000000082271" iyy="0.000011867" iyz="0.00000054005" izz="0.000038478"/>
    </inertial>
  </link>
  <joint name="forkHandle_to_FTMount" type="fixed">
    <parent link="FTMount"/>
    <child link="forkHandle"/>
    <axis xyz="0 0 1"/>
    <origin rpy="-0.025 0 -0.0065" xyz="0 0.005 0.0013"/>
  </joint>
  <link name="forkHandleCover">
    <visual>
      <geometry>
        <mesh filename="package://ada_description/meshes/forque/2024_06_24_forkHandleCover.stl" scale="0.001 0.001 0.001"/>
      </geometry>
      <material name="abs">
        <color rgba="0.4 0.4 0.4 1"/>
      </material>
    </visual>
    <collision>
      <geometry>
        <mesh filename="package://ada_description/meshes/forque/2024_06_24_forkHandleCover.stl" scale="0.001 0.001 0.001"/>
      </geometry>
    </collision>
    <inertial>
      <origin rpy="0 0 0" xyz="0.011157 -0.168451 0.006404"/>
      <mass value="0.004"/>
      <inertia ixx="0.0000027878" ixy="0.00000000012805" ixz="0.00000000006585" iyy="0.00000064518" iyz="0.00000016201" izz="0.000003363634"/>
    </inertial>
  </link>
  <joint name="forkHandleCover_to_forkHandle" type="fixed">
    <parent link="forkHandle"/>
    <child link="forkHandleCover"/>
    <axis xyz="0 0 1"/>
    <origin rpy="0 0 0" xyz="0 0 0"/>
  </joint>
  <link name="forque">
    <visual>
      <geometry>
        <mesh filename="package://ada_description/meshes/forque/ATI-9105-TW-NANO25-E.stl" scale="0.001 0.001 0.001"/>
      </geometry>
      <material name="abs">
        <color rgba="0.4 0.4 0.4 1"/>
      </material>
    </visual>
    <collision>
      <geometry>
        <mesh filename="package://ada_description/meshes/forque/ATI-9105-TW-NANO25-E.stl" scale="0.001 0.001 0.001"/>
      </geometry>
    </collision>
    <inertial>
      <origin rpy="0 0 0" xyz="0.0124692 0.0137169 0.010558"/>
      <mass value="0.0634"/>
      <inertia ixx="0.000005235822" ixy="-0.0000003129932" ixz="0.000000013798" iyy="0.000006264852" iyz="-0.00000004033694" izz="0.00000640797"/>
    </inertial>
  </link>
  <joint name="forque_to_forkHandle" type="fixed">
    <parent link="forkHandle"/>
    <child link="forque"/>
    <axis xyz="0 0 1"/>
    <origin rpy="1.5707963267948966 1.0471975511965976 0" xyz="-0.00634 -0.222553 -0.004286"/>
  </joint>
  <link name="forkTine">
    <visual>
      <geometry>
        <mesh filename="package://ada_description/meshes/forque/fork_tine.stl" scale="0.001 0.001 0.001"/>
      </geometry>
      <material name="abs">
        <color rgba="0.4 0.4 0.4 1"/>
      </material>
    </visual>
    <collision>
      <geometry>
        <mesh filename="package://ada_description/meshes/forque/fork_tine.stl" scale="0.001 0.001 0.001"/>
      </geometry>
    </collision>
    <inertial>
      <origin rpy="0 0 0" xyz="0.013090 0.0180789 0.0445231"/>
      <mass value="0.024"/>
      <inertia ixx="0.0000098769" ixy="0.000000000806182" ixz="-0.00000000296036" iyy="0.000009848103" iyz="0.00000057639" izz="0.0000015674"/>
    </inertial>
  </link>
  <joint name="forkTine_to_forque" type="fixed">
    <parent link="forque"/>
    <child link="forkTine"/>
    <axis xyz="0 0 1"/>
    <origin rpy="0 3.141592653589793 4.1887902047863905" xyz="-0.0054 0.008 0.093"/>
  </joint>
  <link name="forkTip"/>
  <joint name="forkTip_to_forkTine" type="fixed">
    <child link="forkTip"/>
    <parent link="forkTine"/>
    <origin rpy="3.141592653589793 0 0" xyz="0.0135 0.007 0"/>
  </joint>
  <link name="FTSensor"/>
  <joint name="EE_to_FTSensor" type="fixed">
    <child link="FTSensor"/>
    <parent link="ada_end_effector_link"/>
    <!-- gurnoork might have to be actual endeffector? or FTArmMount -->
    <origin rpy="0 0 0" xyz="0.0 0.0 0.092"/>
  </joint>
  <!--xacro:if value="$(arg use_forque)">
    <xacro:forque_assembly base_parent="FTArmMount"/>

    <link name="FTSensor"/>
    <joint
      name="EE_to_FTSensor"
      type="fixed"
    >
      <child link="FTSensor"/>
      <parent link="j2n6s200_end_effector"/>
      <origin
        rpy="0 0 0"
        xyz="0.0 0.0 0.092"
      />
    </joint>
  </xacro:if-->
</robot>
